Workbook

Sheet 📊 Dashboard
A1: 📊 Wedding Dashboard
A2: 🏠 Dashboard | C2: 👥 Guests | E2: 💰 Budget | G2: 🧾 Expenses | I2: 🏪 Vendors | K2: 🛍 Shopping | M2: 📦 Inventory | O2: 🚗 Stay | Q2: ✅ Tasks
A3: =IF('ℹ️ Wedding Info'!B4="","","💍 "&'ℹ️ Wedding Info'!B4&" ❤ "&'ℹ️ Wedding Info'!B5&" | 📅 "&TEXT('ℹ️ Wedding Info'!B6,"dd mmmm yyyy")&IF('ℹ️ Wedding Info'!B8="",""," | 📍 "&'ℹ️ Wedding Info'!B8))
A5: ⏳ WEDDING COUNTDOWN | G5: 📣 LATEST ANNOUNCEMENT
A6: =IF('ℹ️ Wedding Info'!B6="","Set your wedding date in Wedding Info",IF('ℹ️ Wedding Info'!B6-TODAY()<0,"The big day has passed! 🎉",'ℹ️ Wedding Info'!B6-TODAY()&" DAYS TO GO")) -> Set your wedding date in Wedding Info | G6: =IF('ℹ️ Wedding Info'!B29="","No announcements yet — add one in Wedding Info","📅 "&TEXT('ℹ️ Wedding Info'!A29,"dd mmm")&" — "&'ℹ️ Wedding Info'!B29&" ("&'ℹ️ Wedding Info'!C29&")") -> 📅 01 Aug — Caterer tasting moved to Friday 6pm (Rohan)
A8: 🔑 Key Numbers
A9: 💰 Total Budget | E9: 🧾 Total Expenses | I9: 💵 Remaining Budget | M9: 📊 Budget Utilization | R9: 🔢 Chart data (auto)
A10: ='💰 Budget'!B16 -> 0 | E10: ='💰 Budget'!C16 -> 50000 | I10: ='💰 Budget'!D16 -> -50000 | M10: ='💰 Budget'!F16 -> 0 | R10: Not Started | S10: =COUNTIF('✅ Tasks'!G7:G56,"Not Started") -> 0
R11: In Progress | S11: =COUNTIF('✅ Tasks'!G7:G56,"In Progress") -> 1
A12: 👪 Total Families | E12: 👥 Total Members | I12: ✉️ Invitations Pending | M12: 💒 Attending Wedding | R12: Completed | S12: =COUNTIF('✅ Tasks'!G7:G56,"Completed") -> 0
A13: =COUNTA('👨‍👩‍👧‍👦 Guests'!B7:B66) -> 1 | E13: =SUM('👨‍👩‍👧‍👦 Guests'!F7:F66) -> 4 | I13: =COUNTA('👨‍👩‍👧‍👦 Guests'!B7:B66)-COUNTIF('👨‍👩‍👧‍👦 Guests'!G7:G66,"Yes") -> 0 | M13: =COUNTIF('👨‍👩‍👧‍👦 Guests'!J7:J66,TRUE()) -> 1
R14: Invited (Yes) | S14: =COUNTIF('👨‍👩‍👧‍👦 Guests'!G7:G66,"Yes") -> 1
A15: ⏳ Pending Tasks | E15: ⚠️ Overdue Tasks | I15: ✅ Task Progress | M15: 🛍️ Shopping Progress | R15: Not Yet | S15: =COUNTA('👨‍👩‍👧‍👦 Guests'!B7:B66)-S14 -> 0
A16: =COUNTIF('✅ Tasks'!G7:G56,"Not Started")+COUNTIF('✅ Tasks'!G7:G56,"In Progress") -> 1 | E16: =COUNTIFS('✅ Tasks'!F7:F56,"<"&TODAY(),'✅ Tasks'!G7:G56,"<>Completed",'✅ Tasks'!A7:A56,"<>") -> 0 | I16: =IFERROR(COUNTIF('✅ Tasks'!G7:G56,"Completed")/COUNTA('✅ Tasks'!A7:A56),0) -> 0 | M16: =IFERROR(COUNTIF('🛍️ Shopping'!E7:E56,"Completed")/COUNTA('🛍️ Shopping'!A7:A56),0) -> 0
A18: 🏪 Vendor Payments Pending | E18: 💳 Amount Pending | I18: 📦 Inventory Short Items | M18: 🏨 Stay Records
A19: =COUNTIF('🏪 Vendors'!J4:J43,"Pending") -> 1 | E19: =SUMIF('🏪 Vendors'!J4:J43,"Pending",'🏪 Vendors'!I4:I43) -> 450000 | I19: =SUMPRODUCT(('📦 Inventory'!A4:A43<>"")*('📦 Inventory'!C4:C43<'📦 Inventory'!B4:B43)) -> 1 | M19: =COUNTA('🏨 Stay Arrangement'!A7:A46) -> 1
A21: =IFERROR(IF(_xlfn.MINIFS('📅 Timeline'!B4:B17,'📅 Timeline'!B4:B17,">="&TODAY())=0,"🎉 No upcoming events on the Timeline yet","🎉 Next Up: "&INDEX('📅 Timeline'!A4:A17,MATCH(_xlfn.MINIFS('📅 Timeline'!B4:B17,'📅 Timeline'!B4:B17,">="&TODAY()),'📅 Timeline'!B4:B17,0))&" on "&TEXT(_xlfn.MINIFS('📅 Timeline'!B4:B17,'📅 Timeline'!B4:B17,">="&TODAY()),"dd mmmm yyyy")&" at "&INDEX('📅 Timeline'!D4:D17,MATCH(_xlfn.MINIFS('📅 Timeline'!B4:B17,'📅 Timeline'!B4:B17,">="&TODAY()),'📅 Timeline'!B4:B17,0))),"🎉 No upcoming events on the Timeline yet") -> 🎉 Next Up: Engagement on 10 December 2026 at Sharma Residence, Pune
A24: 📈 Visual Breakdown

Sheet 📖 Read Me
A1: 💍 Wedding Management Workbook — Phase 1
B3: What's in this file
B4: 📊 Dashboard and 🔍 Search are both built. The full workbook is complete — every sheet from planning through the wedding day is live and interconnected.
B6: How to import into Google Sheets
B7: • 1. Open Google Drive → New → File upload → select this .xlsx file.
B8: • 2. Right-click the uploaded file → Open with → Google Sheets.
B9: • 3. Google Sheets converts it automatically — formulas, dropdowns, formatting, and frozen headers all carry over.
B10: • 4. File → Save as Google Sheets (or it auto-converts on first edit) so it becomes a native Sheet, not a synced Excel file.
B12: How to read the colors
B13: • White cells with a border = type here. This is where you or your family enter data.
B14: • Grey cells = formulas. Don't type into these — they calculate automatically from your data.
B15: • Blue banner rows = section titles / navigation. Not editable.
B17: After importing — 2 quick Google Sheets-only steps
... B25: • Phase 5: 📊 Dashboard and 🔍 Search (built last, since both pull from every other sheet)

Sheet ⚙️ Settings
A1: Family Members | B1: Wedding Categories | C1: Payment Mode | D1: Expense Status | E1: Yes / No | F1: Invitation Status | G1: Call Status | H1: Confirmation Status | I1: Priority | J1: Shopping Categories | K1: Shopping Status | L1: Inventory Category | M1: Unit | N1: Inventory Status | O1: Task Category | P1: Task Priority | Q1: Task Status | R1: Timeline Event | S1: Timeline Status | T1: Contact Type | U1: Document Category
A2: Father | B2: Hall | C2: Cash | D2: Pending | E2: Yes | F2: Not Printed | G2: Not Called | H2: Confirmed | I2: VIP | J2: Groom Outfits | K2: Not Started | L2: Pooja Items | M2: Pieces | N2: Not Ordered | O2: Venue | P2: High | Q2: Not Started | R2: Engagement | S2: Upcoming | T2: Family | U2: Bill
A3: Mother | B3: Decoration | C3: UPI | D3: Paid | E3: No | F3: Printed | G3: Calling Today | H3: Pending | I3: Close Family | J3: Bride Outfits | K3: Ordered | L3: Decoration | M3: Kg | N3: Ordered | O3: Catering | P3: Medium | Q3: In Progress | R3: Haldi | S3: In Progress | T3: Photographer | U3: Contract
A4: Brother | B4: Food | C4: Card | D4: Cancelled | F4: Given | G4: Called | H4: Not Coming | I4: Relatives | J4: Family Outfits | K4: Purchased | L4: Return Gifts | M4: Boxes | N4: In Hand | O4: Decor | P4: Low | Q4: Completed | R4: Mehendi | S4: Done | T4: Decorator | U4: Invitation Design
A5: Sister | B5: Photography | C5: Bank Transfer | F5: Courier | G5: No Response | I5: Friends | J5: Jewellery | K5: Delivered | L5: Printed Material | M5: Packets | N5: Distributed | O5: Guests | R5: Sangeet | T5: Caterer | U5: Receipt
A6: Uncle | B6: Invitation | C6: Cheque | F6: WhatsApp | G6: Declined | I6: Office | J6: Return Gifts | K6: Alteration Pending | L6: Consumables | M6: Dozens | O6: Shopping | R6: Wedding | T6: Hotel | U6: Important Document
A7: Aunt | B7: Jewellery | F7: Received | I7: Village | J7: Home & Setup | K7: Completed | L7: Other | O7: Documentation | R7: Reception | T7: Transportation | U7: Photo
A8: Cousin | B8: Shopping | I8: Business | J8: Misc | O8: Other | R8: Custom | T8: Emergency | U8: Video
A9: Self | B9: Travel | I9: Others | T9: Other Vendor
A10: Other | B10: Accommodation
B11: Music
B12: Return Gifts
B13: Miscellaneous

Sheet ℹ️ Wedding Info
A1: ℹ️ Wedding Information
A3: Core Details
A4: Bride Name
A5: Groom Name
A6: Wedding Date
A7: Reception Date
A8: Venue
A9: Address | C9: =IF(B9="","",HYPERLINK("https://www.google.com/maps/search/?api=1&query="&SUBSTITUTE(B9," ","+"),"📍 Open in Maps"))
A11: Emergency Contacts
A12: Name | B12: Relation | C12: Phone | D12: Notes
A13: Suresh Kumar | B13: Father | C13: +91 98765 43210 | D13: Primary contact
A19: Important Phone Numbers
A20: Name / Purpose | B20: Phone | C20: Notes
A21: Caterer — Ramesh Catering | B21: +91 90000 11122 | C21: Confirm final count 1 week prior
A27: 📣 Announcements (feeds Dashboard 'Latest Announcements' — Phase 5)
A28: Date | B28: Announcement | C28: Posted By
A29: 46235 | B29: Caterer tasting moved to Friday 6pm | C29: Rohan
A33: Notes

Sheet 💰 Budget
A1: 💰 Budget Planning
A3: Category | B3: Estimated Budget (₹) | C3: Actual Expense (₹) | D3: Difference (₹) | E3: Status | F3: % Used
A4: Hall | B4: 0 | C4: =SUMIF('🧾 Expenses'!$C:$C,A4,'🧾 Expenses'!$F:$F) -> 50000 | D4: =B4-C4 -> -50000 | E4: =IF(B4=0,"—",IF(D4<0,"⚠️ Over Budget",IF(D4=0,"On Budget","✅ Under Budget"))) -> — | F4: =IF(B4=0,0,C4/B4) -> 0
A5: Decoration | B5: 0 | C5: =SUMIF('🧾 Expenses'!$C:$C,A5,'🧾 Expenses'!$F:$F) -> 0 | D5: =B5-C5 -> 0 | E5: =IF(B5=0,"—",IF(D5<0,"⚠️ Over Budget",IF(D5=0,"On Budget","✅ Under Budget"))) -> — | F5: =IF(B5=0,0,C5/B5) -> 0
A6: Food | B6: 0 | C6: =SUMIF('🧾 Expenses'!$C:$C,A6,'🧾 Expenses'!$F:$F) -> 0 | D6: =B6-C6 -> 0 | E6: =IF(B6=0,"—",IF(D6<0,"⚠️ Over Budget",IF(D6=0,"On Budget","✅ Under Budget"))) -> — | F6: =IF(B6=0,0,C6/B6) -> 0
A7: Photography | B7: 0 | C7: =SUMIF('🧾 Expenses'!$C:$C,A7,'🧾 Expenses'!$F:$F) -> 0 | D7: =B7-C7 -> 0 | E7: =IF(B7=0,"—",IF(D7<0,"⚠️ Over Budget",IF(D7=0,"On Budget","✅ Under Budget"))) -> — | F7: =IF(B7=0,0,C7/B7) -> 0
A8: Invitation | B8: 0 | C8: =SUMIF('🧾 Expenses'!$C:$C,A8,'🧾 Expenses'!$F:$F) -> 0 | D8: =B8-C8 -> 0 | E8: =IF(B8=0,"—",IF(D8<0,"⚠️ Over Budget",IF(D8=0,"On Budget","✅ Under Budget"))) -> — | F8: =IF(B8=0,0,C8/B8) -> 0
A9: Jewellery | B9: 0 | C9: =SUMIF('🧾 Expenses'!$C:$C,A9,'🧾 Expenses'!$F:$F) -> 0 | D9: =B9-C9 -> 0 | E9: =IF(B9=0,"—",IF(D9<0,"⚠️ Over Budget",IF(D9=0,"On Budget","✅ Under Budget"))) -> — | F9: =IF(B9=0,0,C9/B9) -> 0
A10: Shopping | B10: 0 | C10: =SUMIF('🧾 Expenses'!$C:$C,A10,'🧾 Expenses'!$F:$F) -> 0 | D10: =B10-C10 -> 0 | E10: =IF(B10=0,"—",IF(D10<0,"⚠️ Over Budget",IF(D10=0,"On Budget","✅ Under Budget"))) -> — | F10: =IF(B10=0,0,C10/B10) -> 0
A11: Travel | B11: 0 | C11: =SUMIF('🧾 Expenses'!$C:$C,A11,'🧾 Expenses'!$F:$F) -> 0 | D11: =B11-C11 -> 0 | E11: =IF(B11=0,"—",IF(D11<0,"⚠️ Over Budget",IF(D11=0,"On Budget","✅ Under Budget"))) -> — | F11: =IF(B11=0,0,C11/B11) -> 0
A12: Accommodation | B12: 0 | C12: =SUMIF('🧾 Expenses'!$C:$C,A12,'🧾 Expenses'!$F:$F) -> 0 | D12: =B12-C12 -> 0 | E12: =IF(B12=0,"—",IF(D12<0,"⚠️ Over Budget",IF(D12=0,"On Budget","✅ Under Budget"))) -> — | F12: =IF(B12=0,0,C12/B12) -> 0
A13: Music | B13: 0 | C13: =SUMIF('🧾 Expenses'!$C:$C,A13,'🧾 Expenses'!$F:$F) -> 0 | D13: =B13-C13 -> 0 | E13: =IF(B13=0,"—",IF(D13<0,"⚠️ Over Budget",IF(D13=0,"On Budget","✅ Under Budget"))) -> — | F13: =IF(B13=0,0,C13/B13) -> 0
A14: Return Gifts | B14: 0 | C14: =SUMIF('🧾 Expenses'!$C:$C,A14,'🧾 Expenses'!$F:$F) -> 0 | D14: =B14-C14 -> 0 | E14: =IF(B14=0,"—",IF(D14<0,"⚠️ Over Budget",IF(D14=0,"On Budget","✅ Under Budget"))) -> — | F14: =IF(B14=0,0,C14/B14) -> 0
A15: Miscellaneous | B15: 0 | C15: =SUMIF('🧾 Expenses'!$C:$C,A15,'🧾 Expenses'!$F:$F) -> 0 | D15: =B15-C15 -> 0 | E15: =IF(B15=0,"—",IF(D15<0,"⚠️ Over Budget",IF(D15=0,"On Budget","✅ Under Budget"))) -> — | F15: =IF(B15=0,0,C15/B15) -> 0
A16: TOTAL | B16: =SUM(B4:B15) -> 0 | C16: =SUM(C4:C15) -> 50000 | D16: =SUM(D4:D15) -> -50000 | E16: =IF(D16<0,"⚠️ Over Budget",IF(D16=0,"On Budget","✅ Under Budget")) -> ⚠️ Over Budget | F16: =IF(B16=0,0,C16/B16) -> 0
A18: Note: 'Actual Expense' pulls automatically from the Expenses sheet by Category. Only edit the white 'Estimated Budget' column here.

Sheet 🧾 Expenses
A1: 🧾 Expense Tracker
A3: Expense ID | B3: Date | C3: Category | D3: Description | E3: Vendor | F3: Amount (₹) | G3: Paid By | H3: Payment Mode | I3: Notes
A4: =IF(COUNTA(B4:I4)=0,"","E"&TEXT(ROW()-3,"000")) -> E001 | B4: 46235 | C4: Hall | D4: Booking advance — Grand Palace Banquets | E4: Grand Palace Banquets | F4: 50000 | G4: Father | H4: Bank Transfer | I4: Advance receipt in Documents folder
A5: =IF(COUNTA(B5:I5)=0,"","E"&TEXT(ROW()-3,"000"))
A6: =IF(COUNTA(B6:I6)=0,"","E"&TEXT(ROW()-3,"000"))
A7: =IF(COUNTA(B7:I7)=0,"","E"&TEXT(ROW()-3,"000"))
A8: =IF(COUNTA(B8:I8)=0,"","E"&TEXT(ROW()-3,"000"))
A9: =IF(COUNTA(B9:I9)=0,"","E"&TEXT(ROW()-3,"000"))
A10: =IF(COUNTA(B10:I10)=0,"","E"&TEXT(ROW()-3,"000"))
A11: =IF(COUNTA(B11:I11)=0,"","E"&TEXT(ROW()-3,"000"))
A12: =IF(COUNTA(B12:I12)=0,"","E"&TEXT(ROW()-3,"000"))
A13: =IF(COUNTA(B13:I13)=0,"","E"&TEXT(ROW()-3,"000"))
A14: =IF(COUNTA(B14:I14)=0,"","E"&TEXT(ROW()-3,"000"))
A15: =IF(COUNTA(B15:I15)=0,"","E"&TEXT(ROW()-3,"000"))
A16: =IF(COUNTA(B16:I16)=0,"","E"&TEXT(ROW()-3,"000"))
... A63: =IF(COUNTA(B63:I63)=0,"","E"&TEXT(ROW()-3,"000"))
E65: TOTAL | F65: =SUM(F4:F63) -> 50000
A67: Expense ID fills in automatically the moment you enter anything in that row — no typing needed. Vendor is free text for now — it becomes a dropdown once Vendor Management (Phase 2) is built.

Sheet 👨‍👩‍👧‍👦 Guests
A1: 👨‍👩‍👧‍👦 Guest Management (family-wise)
A3: 📊 Quick Stats (auto-calculated)
A4: Total Families | D4: Total Members | G4: Invitations Pending | J4: Attending Wedding
A5: =COUNTA(B7:B66) -> 1 | D5: =SUM(F7:F66) -> 4 | G5: =COUNTA(B7:B66)-COUNTIF(G7:G66,"Yes") -> 0 | J5: =COUNTIF(J7:J66,TRUE()) -> 1
A6: Family ID | B6: Family Name / Guest Name | C6: Village/City | D6: Phone Number | E6: WhatsApp Number | F6: Total Members | G6: Invitation Status | H6: Engagement | I6: Haldi | J6: Wedding | K6: Notes
A7: =IF(B7="","","F"&TEXT(ROW()-6,"000")) -> F001 | B7: Sharma Family | C7: Pune | D7: +91 98765 11111 | E7: +91 98765 11111 | F7: 4 | G7: Yes | H7: =TRUE() -> TRUE | I7: =TRUE() -> TRUE | J7: =TRUE() -> TRUE | K7: Confirmed via WhatsApp with uncle | L7: =IF('🔍 Search'!$B$2="",B7<>"",ISNUMBER(SEARCH('🔍 Search'!$B$2,B7&" "&C7&" "&D7&" "&E7&" "&K7))) -> TRUE | M7: =IF(L7,COUNTIF($L$7:L7,TRUE()),"") -> 1
A8: =IF(B8="","","F"&TEXT(ROW()-6,"000")) | H8: =FALSE() -> FALSE | I8: =FALSE() -> FALSE | J8: =FALSE() -> FALSE | L8: =IF('🔍 Search'!$B$2="",B8<>"",ISNUMBER(SEARCH('🔍 Search'!$B$2,B8&" "&C8&" "&D8&" "&E8&" "&K8))) -> FALSE | M8: =IF(L8,COUNTIF($L$7:L8,TRUE()),"")
A9: =IF(B9="","","F"&TEXT(ROW()-6,"000")) | H9: =FALSE() -> FALSE | I9: =FALSE() -> FALSE | J9: =FALSE() -> FALSE | L9: =IF('🔍 Search'!$B$2="",B9<>"",ISNUMBER(SEARCH('🔍 Search'!$B$2,B9&" "&C9&" "&D9&" "&E9&" "&K9))) -> FALSE | M9: =IF(L9,COUNTIF($L$7:L9,TRUE()),"")
A10: =IF(B10="","","F"&TEXT(ROW()-6,"000")) | H10: =FALSE() -> FALSE | I10: =FALSE() -> FALSE | J10: =FALSE() -> FALSE | L10: =IF('🔍 Search'!$B$2="",B10<>"",ISNUMBER(SEARCH('🔍 Search'!$B$2,B10&" "&C10&" "&D10&" "&E10&" "&K10))) -> FALSE | M10: =IF(L10,COUNTIF($L$7:L10,TRUE()),"")
A11: =IF(B11="","","F"&TEXT(ROW()-6,"000")) | H11: =FALSE() -> FALSE | I11: =FALSE() -> FALSE | J11: =FALSE() -> FALSE | L11: =IF('🔍 Search'!$B$2="",B11<>"",ISNUMBER(SEARCH('🔍 Search'!$B$2,B11&" "&C11&" "&D11&" "&E11&" "&K11))) -> FALSE | M11: =IF(L11,COUNTIF($L$7:L11,TRUE()),"")
A12: =IF(B12="","","F"&TEXT(ROW()-6,"000")) | H12: =FALSE() -> FALSE | I12: =FALSE() -> FALSE | J12: =FALSE() -> FALSE | L12: =IF('🔍 Search'!$B$2="",B12<>"",ISNUMBER(SEARCH('🔍 Search'!$B$2,B12&" "&C12&" "&D12&" "&E12&" "&K12))) -> FALSE | M12: =IF(L12,COUNTIF($L$7:L12,TRUE()),"")
A13: =IF(B13="","","F"&TEXT(ROW()-6,"000")) | H13: =FALSE() -> FALSE | I13: =FALSE() -> FALSE | J13: =FALSE() -> FALSE | L13: =IF('🔍 Search'!$B$2="",B13<>"",ISNUMBER(SEARCH('🔍 Search'!$B$2,B13&" "&C13&" "&D13&" "&E13&" "&K13))) -> FALSE | M13: =IF(L13,COUNTIF($L$7:L13,TRUE()),"")
A14: =IF(B14="","","F"&TEXT(ROW()-6,"000")) | H14: =FALSE() -> FALSE | I14: =FALSE() -> FALSE | J14: =FALSE() -> FALSE | L14: =IF('🔍 Search'!$B$2="",B14<>"",ISNUMBER(SEARCH('🔍 Search'!$B$2,B14&" "&C14&" "&D14&" "&E14&" "&K14))) -> FALSE | M14: =IF(L14,COUNTIF($L$7:L14,TRUE()),"")
A15: =IF(B15="","","F"&TEXT(ROW()-6,"000")) | H15: =FALSE() -> FALSE | I15: =FALSE() -> FALSE | J15: =FALSE() -> FALSE | L15: =IF('🔍 Search'!$B$2="",B15<>"",ISNUMBER(SEARCH('🔍 Search'!$B$2,B15&" "&C15&" "&D15&" "&E15&" "&K15))) -> FALSE | M15: =IF(L15,COUNTIF($L$7:L15,TRUE()),"")
A16: =IF(B16="","","F"&TEXT(ROW()-6,"000")) | H16: =FALSE() -> FALSE | I16: =FALSE() -> FALSE | J16: =FALSE() -> FALSE | L16: =IF('🔍 Search'!$B$2="",B16<>"",ISNUMBER(SEARCH('🔍 Search'!$B$2,B16&" "&C16&" "&D16&" "&E16&" "&K16))) -> FALSE | M16: =IF(L16,COUNTIF($L$7:L16,TRUE()),"")
A17: =IF(B17="","","F"&TEXT(ROW()-6,"000")) | H17: =FALSE() -> FALSE | I17: =FALSE() -> FALSE | J17: =FALSE() -> FALSE | L17: =IF('🔍 Search'!$B$2="",B17<>"",ISNUMBER(SEARCH('🔍 Search'!$B$2,B17&" "&C17&" "&D17&" "&E17&" "&K17))) -> FALSE | M17: =IF(L17,COUNTIF($L$7:L17,TRUE()),"")
A18: =IF(B18="","","F"&TEXT(ROW()-6,"000")) | H18: =FALSE() -> FALSE | I18: =FALSE() -> FALSE | J18: =FALSE() -> FALSE | L18: =IF('🔍 Search'!$B$2="",B18<>"",ISNUMBER(SEARCH('🔍 Search'!$B$2,B18&" "&C18&" "&D18&" "&E18&" "&K18))) -> FALSE | M18: =IF(L18,COUNTIF($L$7:L18,TRUE()),"")
A19: =IF(B19="","","F"&TEXT(ROW()-6,"000")) | H19: =FALSE() -> FALSE | I19: =FALSE() -> FALSE | J19: =FALSE() -> FALSE | L19: =IF('🔍 Search'!$B$2="",B19<>"",ISNUMBER(SEARCH('🔍 Search'!$B$2,B19&" "&C19&" "&D19&" "&E19&" "&K19))) -> FALSE | M19: =IF(L19,COUNTIF($L$7:L19,TRUE()),"")
... A66: =IF(B66="","","F"&TEXT(ROW()-6,"000")) | H66: =FALSE() -> FALSE | I66: =FALSE() -> FALSE | J66: =FALSE() -> FALSE | L66: =IF('🔍 Search'!$B$2="",B66<>"",ISNUMBER(SEARCH('🔍 Search'!$B$2,B66&" "&C66&" "&D66&" "&E66&" "&K66))) -> FALSE | M66: =IF(L66,COUNTIF($L$7:L66,TRUE()),"")
A68: Family ID fills in automatically once you type a Family Name. Engagement/Haldi/Wedding are checkboxes — tick as many as apply per family. Rows tint amber while Invitation Status is 'No' and green once it's 'Yes'.

Sheet 🏪 Vendors
A1: 🏪 Vendor Management
A3: Vendor Name | B3: Category | C3: Handled By | D3: Phone | E3: Alternate Phone | F3: Address | G3: Total Amount (₹) | H3: Advance Paid (₹) | I3: Remaining Amount (₹) | J3: Status | K3: Notes
A4: Grand Palace Banquets | B4: Hall | C4: Father | D4: +91 90000 22233 | F4: 123 MG Road, Pune | G4: 500000 | H4: 50000 | I4: =IF(A4="","",G4-H4) -> 450000 | J4: =IF(A4="","",IF(I4<=0,"✅ Fully Paid","Pending")) -> Pending | K4: Includes decoration for mandap | L4: =IF('🔍 Search'!$B$2="",A4<>"",ISNUMBER(SEARCH('🔍 Search'!$B$2,A4&" "&B4&" "&C4&" "&D4&" "&K4))) -> TRUE | M4: =IF(L4,COUNTIF($L$4:L4,TRUE()),"") -> 1
I5: =IF(A5="","",G5-H5) | J5: =IF(A5="","",IF(I5<=0,"✅ Fully Paid","Pending")) | L5: =IF('🔍 Search'!$B$2="",A5<>"",ISNUMBER(SEARCH('🔍 Search'!$B$2,A5&" "&B5&" "&C5&" "&D5&" "&K5))) -> FALSE | M5: =IF(L5,COUNTIF($L$4:L5,TRUE()),"")
I6: =IF(A6="","",G6-H6) | J6: =IF(A6="","",IF(I6<=0,"✅ Fully Paid","Pending")) | L6: =IF('🔍 Search'!$B$2="",A6<>"",ISNUMBER(SEARCH('🔍 Search'!$B$2,A6&" "&B6&" "&C6&" "&D6&" "&K6))) -> FALSE | M6: =IF(L6,COUNTIF($L$4:L6,TRUE()),"")
I7: =IF(A7="","",G7-H7) | J7: =IF(A7="","",IF(I7<=0,"✅ Fully Paid","Pending")) | L7: =IF('🔍 Search'!$B$2="",A7<>"",ISNUMBER(SEARCH('🔍 Search'!$B$2,A7&" "&B7&" "&C7&" "&D7&" "&K7))) -> FALSE | M7: =IF(L7,COUNTIF($L$4:L7,TRUE()),"")
I8: =IF(A8="","",G8-H8) | J8: =IF(A8="","",IF(I8<=0,"✅ Fully Paid","Pending")) | L8: =IF('🔍 Search'!$B$2="",A8<>"",ISNUMBER(SEARCH('🔍 Search'!$B$2,A8&" "&B8&" "&C8&" "&D8&" "&K8))) -> FALSE | M8: =IF(L8,COUNTIF($L$4:L8,TRUE()),"")
I9: =IF(A9="","",G9-H9) | J9: =IF(A9="","",IF(I9<=0,"✅ Fully Paid","Pending")) | L9: =IF('🔍 Search'!$B$2="",A9<>"",ISNUMBER(SEARCH('🔍 Search'!$B$2,A9&" "&B9&" "&C9&" "&D9&" "&K9))) -> FALSE | M9: =IF(L9,COUNTIF($L$4:L9,TRUE()),"")
I10: =IF(A10="","",G10-H10) | J10: =IF(A10="","",IF(I10<=0,"✅ Fully Paid","Pending")) | L10: =IF('🔍 Search'!$B$2="",A10<>"",ISNUMBER(SEARCH('🔍 Search'!$B$2,A10&" "&B10&" "&C10&" "&D10&" "&K10))) -> FALSE | M10: =IF(L10,COUNTIF($L$4:L10,TRUE()),"")
I11: =IF(A11="","",G11-H11) | J11: =IF(A11="","",IF(I11<=0,"✅ Fully Paid","Pending")) | L11: =IF('🔍 Search'!$B$2="",A11<>"",ISNUMBER(SEARCH('🔍 Search'!$B$2,A11&" "&B11&" "&C11&" "&D11&" "&K11))) -> FALSE | M11: =IF(L11,COUNTIF($L$4:L11,TRUE()),"")
I12: =IF(A12="","",G12-H12) | J12: =IF(A12="","",IF(I12<=0,"✅ Fully Paid","Pending")) | L12: =IF('🔍 Search'!$B$2="",A12<>"",ISNUMBER(SEARCH('🔍 Search'!$B$2,A12&" "&B12&" "&C12&" "&D12&" "&K12))) -> FALSE | M12: =IF(L12,COUNTIF($L$4:L12,TRUE()),"")
I13: =IF(A13="","",G13-H13) | J13: =IF(A13="","",IF(I13<=0,"✅ Fully Paid","Pending")) | L13: =IF('🔍 Search'!$B$2="",A13<>"",ISNUMBER(SEARCH('🔍 Search'!$B$2,A13&" "&B13&" "&C13&" "&D13&" "&K13))) -> FALSE | M13: =IF(L13,COUNTIF($L$4:L13,TRUE()),"")
I14: =IF(A14="","",G14-H14) | J14: =IF(A14="","",IF(I14<=0,"✅ Fully Paid","Pending")) | L14: =IF('🔍 Search'!$B$2="",A14<>"",ISNUMBER(SEARCH('🔍 Search'!$B$2,A14&" "&B14&" "&C14&" "&D14&" "&K14))) -> FALSE | M14: =IF(L14,COUNTIF($L$4:L14,TRUE()),"")
I15: =IF(A15="","",G15-H15) | J15: =IF(A15="","",IF(I15<=0,"✅ Fully Paid","Pending")) | L15: =IF('🔍 Search'!$B$2="",A15<>"",ISNUMBER(SEARCH('🔍 Search'!$B$2,A15&" "&B15&" "&C15&" "&D15&" "&K15))) -> FALSE | M15: =IF(L15,COUNTIF($L$4:L15,TRUE()),"")
I16: =IF(A16="","",G16-H16) | J16: =IF(A16="","",IF(I16<=0,"✅ Fully Paid","Pending")) | L16: =IF('🔍 Search'!$B$2="",A16<>"",ISNUMBER(SEARCH('🔍 Search'!$B$2,A16&" "&B16&" "&C16&" "&D16&" "&K16))) -> FALSE | M16: =IF(L16,COUNTIF($L$4:L16,TRUE()),"")
... I43: =IF(A43="","",G43-H43) | J43: =IF(A43="","",IF(I43<=0,"✅ Fully Paid","Pending")) | L43: =IF('🔍 Search'!$B$2="",A43<>"",ISNUMBER(SEARCH('🔍 Search'!$B$2,A43&" "&B43&" "&C43&" "&D43&" "&K43))) -> FALSE | M43: =IF(L43,COUNTIF($L$4:L43,TRUE()),"")
A45: Remaining Amount and Status calculate automatically — only edit the white cells. This sheet also feeds the Vendor dropdown on the Expenses sheet.

Sheet 🛍️ Shopping
A1: 🛍️ Shopping Tracker
A3: 📊 Quick Stats (auto-calculated)
A4: Shopping Progress | C4: Remaining Items | E4: Total Shopping Cost (₹)
A5: =IFERROR(COUNTIF(E7:E56,"Completed")/COUNTA(A7:A56),0) -> 0 | C5: =COUNTA(A7:A56)-COUNTIF(E7:E56,"Completed") -> 1 | E5: =SUM(D7:D56) -> 23000
A6: Item | B6: Category | C6: Responsible Person | D6: Actual Cost (₹) | E6: Status | F6: Notes
A7: Groom Sherwani | B7: Groom Outfits | C7: Self | D7: 23000 | E7: Ordered | F7: Fitting scheduled next week | L7: =IF('🔍 Search'!$B$2="",A7<>"",ISNUMBER(SEARCH('🔍 Search'!$B$2,A7&" "&B7&" "&C7&" "&F7))) -> TRUE | M7: =IF(L7,COUNTIF($L$7:L7,TRUE()),"") -> 1
L8: =IF('🔍 Search'!$B$2="",A8<>"",ISNUMBER(SEARCH('🔍 Search'!$B$2,A8&" "&B8&" "&C8&" "&F8))) -> FALSE | M8: =IF(L8,COUNTIF($L$7:L8,TRUE()),"")
L9: =IF('🔍 Search'!$B$2="",A9<>"",ISNUMBER(SEARCH('🔍 Search'!$B$2,A9&" "&B9&" "&C9&" "&F9))) -> FALSE | M9: =IF(L9,COUNTIF($L$7:L9,TRUE()),"")
L10: =IF('🔍 Search'!$B$2="",A10<>"",ISNUMBER(SEARCH('🔍 Search'!$B$2,A10&" "&B10&" "&C10&" "&F10))) -> FALSE | M10: =IF(L10,COUNTIF($L$7:L10,TRUE()),"")
L11: =IF('🔍 Search'!$B$2="",A11<>"",ISNUMBER(SEARCH('🔍 Search'!$B$2,A11&" "&B11&" "&C11&" "&F11))) -> FALSE | M11: =IF(L11,COUNTIF($L$7:L11,TRUE()),"")
L12: =IF('🔍 Search'!$B$2="",A12<>"",ISNUMBER(SEARCH('🔍 Search'!$B$2,A12&" "&B12&" "&C12&" "&F12))) -> FALSE | M12: =IF(L12,COUNTIF($L$7:L12,TRUE()),"")
L13: =IF('🔍 Search'!$B$2="",A13<>"",ISNUMBER(SEARCH('🔍 Search'!$B$2,A13&" "&B13&" "&C13&" "&F13))) -> FALSE | M13: =IF(L13,COUNTIF($L$7:L13,TRUE()),"")
L14: =IF('🔍 Search'!$B$2="",A14<>"",ISNUMBER(SEARCH('🔍 Search'!$B$2,A14&" "&B14&" "&C14&" "&F14))) -> FALSE | M14: =IF(L14,COUNTIF($L$7:L14,TRUE()),"")
L15: =IF('🔍 Search'!$B$2="",A15<>"",ISNUMBER(SEARCH('🔍 Search'!$B$2,A15&" "&B15&" "&C15&" "&F15))) -> FALSE | M15: =IF(L15,COUNTIF($L$7:L15,TRUE()),"")
L16: =IF('🔍 Search'!$B$2="",A16<>"",ISNUMBER(SEARCH('🔍 Search'!$B$2,A16&" "&B16&" "&C16&" "&F16))) -> FALSE | M16: =IF(L16,COUNTIF($L$7:L16,TRUE()),"")
L17: =IF('🔍 Search'!$B$2="",A17<>"",ISNUMBER(SEARCH('🔍 Search'!$B$2,A17&" "&B17&" "&C17&" "&F17))) -> FALSE | M17: =IF(L17,COUNTIF($L$7:L17,TRUE()),"")
L18: =IF('🔍 Search'!$B$2="",A18<>"",ISNUMBER(SEARCH('🔍 Search'!$B$2,A18&" "&B18&" "&C18&" "&F18))) -> FALSE | M18: =IF(L18,COUNTIF($L$7:L18,TRUE()),"")
L19: =IF('🔍 Search'!$B$2="",A19<>"",ISNUMBER(SEARCH('🔍 Search'!$B$2,A19&" "&B19&" "&C19&" "&F19))) -> FALSE | M19: =IF(L19,COUNTIF($L$7:L19,TRUE()),"")
... L56: =IF('🔍 Search'!$B$2="",A56<>"",ISNUMBER(SEARCH('🔍 Search'!$B$2,A56&" "&B56&" "&C56&" "&F56))) -> FALSE | M56: =IF(L56,COUNTIF($L$7:L56,TRUE()),"")
A58: Status color-codes automatically as items move through their stages. 'Total Shopping Cost' sums Actual Cost — add both bride and groom items here using the Category dropdown.

Sheet 📦 Inventory
A1: 📦 Inventory
A3: Item | B3: Required Qty | C3: Available Qty | D3: Responsible Person | E3: Status | F3: Notes
A4: Invitation Cards | B4: 150 | C4: 100 | D4: Mother | E4: Ordered | F4: Confirmed with gift vendor
A5: Return Gifts
A6: Flowers
A7: Garlands
A8: Coconut
A9: Rice
A10: Pooja Material
A11: Water Bottles
A12: Decoration Items
A45: Column A is pre-filled with common items as a starting point — overwrite or add your own freely. Available Qty highlights red automatically whenever it's short of Required Qty.

Sheet 🏨 Stay Arrangement
A1: 🏨 Stay Arrangement
A3: 📊 Quick Stats (auto-calculated)
A4: Total Families (Guest List) | C4: Stay Records Added
A5: =COUNTA('👨‍👩‍👧‍👦 Guests'!$B$7:$B$66) -> 1 | C5: =COUNTA(A7:A46) -> 1
A6: Family Name / Guest Name | B6: Villa | C6: Address | D6: Responsible Person | E6: Notes
A7: Sharma Family | B7: Hotel Sunview | C7: 45 Lakeside Road, Pune | D7: Brother | E7: Arriving 2 days early, needs early check-in
A48: 'Family Name / Guest Name' dropdown pulls directly from Guest Management. Only add a row here for families who actually need accommodation arranged.

Sheet ✅ Tasks
A1: ✅ Task Tracker
A3: 📊 Quick Stats (auto-calculated)
A4: Pending Tasks | C4: Completed Tasks | E4: Overdue Tasks | G4: Overall Progress
A5: =COUNTIF(G7:G56,"Not Started")+COUNTIF(G7:G56,"In Progress") -> 1 | C5: =COUNTIF(G7:G56,"Completed") -> 0 | E5: =COUNTIFS(F7:F56,"<"&TODAY(),G7:G56,"<>Completed",A7:A56,"<>") -> 0 | G5: =IFERROR(COUNTIF(G7:G56,"Completed")/COUNTA(A7:A56),0) -> 0
A6: Task | B6: Category | C6: Assigned To | D6: Priority | E6: Start Date | F6: Due Date | G6: Status | H6: Comments
A7: Finalize catering menu | B7: Catering | C7: Mother | D7: High | E7: 46239 | F7: 46249 | G7: In Progress | H7: Tasting scheduled with 2 caterers | L7: =IF('🔍 Search'!$B$2="",A7<>"",ISNUMBER(SEARCH('🔍 Search'!$B$2,A7&" "&B7&" "&C7&" "&H7))) -> TRUE | M7: =IF(L7,COUNTIF($L$7:L7,TRUE()),"") -> 1
L8: =IF('🔍 Search'!$B$2="",A8<>"",ISNUMBER(SEARCH('🔍 Search'!$B$2,A8&" "&B8&" "&C8&" "&H8))) -> FALSE | M8: =IF(L8,COUNTIF($L$7:L8,TRUE()),"")
L9: =IF('🔍 Search'!$B$2="",A9<>"",ISNUMBER(SEARCH('🔍 Search'!$B$2,A9&" "&B9&" "&C9&" "&H9))) -> FALSE | M9: =IF(L9,COUNTIF($L$7:L9,TRUE()),"")
L10: =IF('🔍 Search'!$B$2="",A10<>"",ISNUMBER(SEARCH('🔍 Search'!$B$2,A10&" "&B10&" "&C10&" "&H10))) -> FALSE | M10: =IF(L10,COUNTIF($L$7:L10,TRUE()),"")
L11: =IF('🔍 Search'!$B$2="",A11<>"",ISNUMBER(SEARCH('🔍 Search'!$B$2,A11&" "&B11&" "&C11&" "&H11))) -> FALSE | M11: =IF(L11,COUNTIF($L$7:L11,TRUE()),"")
L12: =IF('🔍 Search'!$B$2="",A12<>"",ISNUMBER(SEARCH('🔍 Search'!$B$2,A12&" "&B12&" "&C12&" "&H12))) -> FALSE | M12: =IF(L12,COUNTIF($L$7:L12,TRUE()),"")
L13: =IF('🔍 Search'!$B$2="",A13<>"",ISNUMBER(SEARCH('🔍 Search'!$B$2,A13&" "&B13&" "&C13&" "&H13))) -> FALSE | M13: =IF(L13,COUNTIF($L$7:L13,TRUE()),"")
L14: =IF('🔍 Search'!$B$2="",A14<>"",ISNUMBER(SEARCH('🔍 Search'!$B$2,A14&" "&B14&" "&C14&" "&H14))) -> FALSE | M14: =IF(L14,COUNTIF($L$7:L14,TRUE()),"")
L15: =IF('🔍 Search'!$B$2="",A15<>"",ISNUMBER(SEARCH('🔍 Search'!$B$2,A15&" "&B15&" "&C15&" "&H15))) -> FALSE | M15: =IF(L15,COUNTIF($L$7:L15,TRUE()),"")
L16: =IF('🔍 Search'!$B$2="",A16<>"",ISNUMBER(SEARCH('🔍 Search'!$B$2,A16&" "&B16&" "&C16&" "&H16))) -> FALSE | M16: =IF(L16,COUNTIF($L$7:L16,TRUE()),"")
L17: =IF('🔍 Search'!$B$2="",A17<>"",ISNUMBER(SEARCH('🔍 Search'!$B$2,A17&" "&B17&" "&C17&" "&H17))) -> FALSE | M17: =IF(L17,COUNTIF($L$7:L17,TRUE()),"")
L18: =IF('🔍 Search'!$B$2="",A18<>"",ISNUMBER(SEARCH('🔍 Search'!$B$2,A18&" "&B18&" "&C18&" "&H18))) -> FALSE | M18: =IF(L18,COUNTIF($L$7:L18,TRUE()),"")
L19: =IF('🔍 Search'!$B$2="",A19<>"",ISNUMBER(SEARCH('🔍 Search'!$B$2,A19&" "&B19&" "&C19&" "&H19))) -> FALSE | M19: =IF(L19,COUNTIF($L$7:L19,TRUE()),"")
... L56: =IF('🔍 Search'!$B$2="",A56<>"",ISNUMBER(SEARCH('🔍 Search'!$B$2,A56&" "&B56&" "&C56&" "&H56))) -> FALSE | M56: =IF(L56,COUNTIF($L$7:L56,TRUE()),"")
A58: A Due Date turns red automatically once it's passed and Status isn't 'Completed' — that's what powers the Overdue Tasks count above.

Sheet 📅 Timeline
A1: 📅 Wedding Timeline
A3: Event | B3: Date | C3: Time | D3: Venue | E3: Responsible Person | F3: Checklist | G3: Status | H3: Notes
A4: Engagement | B4: 46366 | C4: 0.75 | D4: Sharma Residence, Pune | E4: Mother | F4: Book priest, arrange sweets | G4: Upcoming
A5: Haldi
A6: Mehendi
A7: Sangeet
A8: Wedding
A9: Reception
A19: The 6 standard function rows are pre-filled to save typing — edit dates/venues freely, delete any that don't apply, or use 'Custom' for anything extra (Griha Pravesh, pre-wedding shoot, etc.).

Sheet 📇 Contacts
A1: 📇 Contact Directory
A3: 👪 Family & Emergency Contacts (auto-synced from ℹ️ Wedding Info — edit them there)
A4: Name | B4: Type | C4: Phone | D4: Alternate Phone | E4: Notes
A5: =IF('ℹ️ Wedding Info'!A13="","",'ℹ️ Wedding Info'!A13&"") -> Suresh Kumar | B5: =IF('ℹ️ Wedding Info'!A13="","","Emergency ("&'ℹ️ Wedding Info'!B13&")") -> Emergency (Father) | C5: =IF('ℹ️ Wedding Info'!A13="","",'ℹ️ Wedding Info'!C13&"") -> +91 98765 43210 | E5: =IF('ℹ️ Wedding Info'!A13="","",'ℹ️ Wedding Info'!D13&"") -> Primary contact
A6: =IF('ℹ️ Wedding Info'!A14="","",'ℹ️ Wedding Info'!A14&"") | B6: =IF('ℹ️ Wedding Info'!A14="","","Emergency ("&'ℹ️ Wedding Info'!B14&")") | C6: =IF('ℹ️ Wedding Info'!A14="","",'ℹ️ Wedding Info'!C14&"") | E6: =IF('ℹ️ Wedding Info'!A14="","",'ℹ️ Wedding Info'!D14&"")
A7: =IF('ℹ️ Wedding Info'!A15="","",'ℹ️ Wedding Info'!A15&"") | B7: =IF('ℹ️ Wedding Info'!A15="","","Emergency ("&'ℹ️ Wedding Info'!B15&")") | C7: =IF('ℹ️ Wedding Info'!A15="","",'ℹ️ Wedding Info'!C15&"") | E7: =IF('ℹ️ Wedding Info'!A15="","",'ℹ️ Wedding Info'!D15&"")
A8: =IF('ℹ️ Wedding Info'!A16="","",'ℹ️ Wedding Info'!A16&"") | B8: =IF('ℹ️ Wedding Info'!A16="","","Emergency ("&'ℹ️ Wedding Info'!B16&")") | C8: =IF('ℹ️ Wedding Info'!A16="","",'ℹ️ Wedding Info'!C16&"") | E8: =IF('ℹ️ Wedding Info'!A16="","",'ℹ️ Wedding Info'!D16&"")
A9: =IF('ℹ️ Wedding Info'!A17="","",'ℹ️ Wedding Info'!A17&"") | B9: =IF('ℹ️ Wedding Info'!A17="","","Emergency ("&'ℹ️ Wedding Info'!B17&")") | C9: =IF('ℹ️ Wedding Info'!A17="","",'ℹ️ Wedding Info'!C17&"") | E9: =IF('ℹ️ Wedding Info'!A17="","",'ℹ️ Wedding Info'!D17&"")
A10: =IF('ℹ️ Wedding Info'!A21="","",'ℹ️ Wedding Info'!A21&"") -> Caterer — Ramesh Catering | B10: =IF('ℹ️ Wedding Info'!A21="","","Important Number") -> Important Number | C10: =IF('ℹ️ Wedding Info'!A21="","",'ℹ️ Wedding Info'!B21&"") -> +91 90000 11122 | E10: =IF('ℹ️ Wedding Info'!A21="","",'ℹ️ Wedding Info'!C21&"") -> Confirm final count 1 week prior
A11: =IF('ℹ️ Wedding Info'!A22="","",'ℹ️ Wedding Info'!A22&"") | B11: =IF('ℹ️ Wedding Info'!A22="","","Important Number") | C11: =IF('ℹ️ Wedding Info'!A22="","",'ℹ️ Wedding Info'!B22&"") | E11: =IF('ℹ️ Wedding Info'!A22="","",'ℹ️ Wedding Info'!C22&"")
A12: =IF('ℹ️ Wedding Info'!A23="","",'ℹ️ Wedding Info'!A23&"") | B12: =IF('ℹ️ Wedding Info'!A23="","","Important Number") | C12: =IF('ℹ️ Wedding Info'!A23="","",'ℹ️ Wedding Info'!B23&"") | E12: =IF('ℹ️ Wedding Info'!A23="","",'ℹ️ Wedding Info'!C23&"")
A13: =IF('ℹ️ Wedding Info'!A24="","",'ℹ️ Wedding Info'!A24&"") | B13: =IF('ℹ️ Wedding Info'!A24="","","Important Number") | C13: =IF('ℹ️ Wedding Info'!A24="","",'ℹ️ Wedding Info'!B24&"") | E13: =IF('ℹ️ Wedding Info'!A24="","",'ℹ️ Wedding Info'!C24&"")
A14: =IF('ℹ️ Wedding Info'!A25="","",'ℹ️ Wedding Info'!A25&"") | B14: =IF('ℹ️ Wedding Info'!A25="","","Important Number") | C14: =IF('ℹ️ Wedding Info'!A25="","",'ℹ️ Wedding Info'!B25&"") | E14: =IF('ℹ️ Wedding Info'!A25="","",'ℹ️ Wedding Info'!C25&"")
A16: 🏪 Vendor Contacts (auto-synced from 🏪 Vendors — edit them there)
A17: Name | B17: Type | C17: Phone | D17: Alternate Phone | E17: Notes
A18: =IF('🏪 Vendors'!A4="","",'🏪 Vendors'!A4&"") -> Grand Palace Banquets | B18: =IF('🏪 Vendors'!A4="","",'🏪 Vendors'!B4&" Vendor") -> Hall Vendor | C18: =IF('🏪 Vendors'!A4="","",'🏪 Vendors'!D4&"") -> +91 90000 22233 | D18: =IF('🏪 Vendors'!A4="","",'🏪 Vendors'!E4&"") | E18: =IF('🏪 Vendors'!A4="","","Handled by "&'🏪 Vendors'!C4) -> Handled by Father
A19: =IF('🏪 Vendors'!A5="","",'🏪 Vendors'!A5&"") | B19: =IF('🏪 Vendors'!A5="","",'🏪 Vendors'!B5&" Vendor") | C19: =IF('🏪 Vendors'!A5="","",'🏪 Vendors'!D5&"") | D19: =IF('🏪 Vendors'!A5="","",'🏪 Vendors'!E5&"") | E19: =IF('🏪 Vendors'!A5="","","Handled by "&'🏪 Vendors'!C5)
A20: =IF('🏪 Vendors'!A6="","",'🏪 Vendors'!A6&"") | B20: =IF('🏪 Vendors'!A6="","",'🏪 Vendors'!B6&" Vendor") | C20: =IF('🏪 Vendors'!A6="","",'🏪 Vendors'!D6&"") | D20: =IF('🏪 Vendors'!A6="","",'🏪 Vendors'!E6&"") | E20: =IF('🏪 Vendors'!A6="","","Handled by "&'🏪 Vendors'!C6)
A21: =IF('🏪 Vendors'!A7="","",'🏪 Vendors'!A7&"") | B21: =IF('🏪 Vendors'!A7="","",'🏪 Vendors'!B7&" Vendor") | C21: =IF('🏪 Vendors'!A7="","",'🏪 Vendors'!D7&"") | D21: =IF('🏪 Vendors'!A7="","",'🏪 Vendors'!E7&"") | E21: =IF('🏪 Vendors'!A7="","","Handled by "&'🏪 Vendors'!C7)
A22: =IF('🏪 Vendors'!A8="","",'🏪 Vendors'!A8&"") | B22: =IF('🏪 Vendors'!A8="","",'🏪 Vendors'!B8&" Vendor") | C22: =IF('🏪 Vendors'!A8="","",'🏪 Vendors'!D8&"") | D22: =IF('🏪 Vendors'!A8="","",'🏪 Vendors'!E8&"") | E22: =IF('🏪 Vendors'!A8="","","Handled by "&'🏪 Vendors'!C8)
A23: =IF('🏪 Vendors'!A9="","",'🏪 Vendors'!A9&"") | B23: =IF('🏪 Vendors'!A9="","",'🏪 Vendors'!B9&" Vendor") | C23: =IF('🏪 Vendors'!A9="","",'🏪 Vendors'!D9&"") | D23: =IF('🏪 Vendors'!A9="","",'🏪 Vendors'!E9&"") | E23: =IF('🏪 Vendors'!A9="","","Handled by "&'🏪 Vendors'!C9)
A24: =IF('🏪 Vendors'!A10="","",'🏪 Vendors'!A10&"") | B24: =IF('🏪 Vendors'!A10="","",'🏪 Vendors'!B10&" Vendor") | C24: =IF('🏪 Vendors'!A10="","",'🏪 Vendors'!D10&"") | D24: =IF('🏪 Vendors'!A10="","",'🏪 Vendors'!E10&"") | E24: =IF('🏪 Vendors'!A10="","","Handled by "&'🏪 Vendors'!C10)
A25: =IF('🏪 Vendors'!A11="","",'🏪 Vendors'!A11&"") | B25: =IF('🏪 Vendors'!A11="","",'🏪 Vendors'!B11&" Vendor") | C25: =IF('🏪 Vendors'!A11="","",'🏪 Vendors'!D11&"") | D25: =IF('🏪 Vendors'!A11="","",'🏪 Vendors'!E11&"") | E25: =IF('🏪 Vendors'!A11="","","Handled by "&'🏪 Vendors'!C11)
A26: =IF('🏪 Vendors'!A12="","",'🏪 Vendors'!A12&"") | B26: =IF('🏪 Vendors'!A12="","",'🏪 Vendors'!B12&" Vendor") | C26: =IF('🏪 Vendors'!A12="","",'🏪 Vendors'!D12&"") | D26: =IF('🏪 Vendors'!A12="","",'🏪 Vendors'!E12&"") | E26: =IF('🏪 Vendors'!A12="","","Handled by "&'🏪 Vendors'!C12)
A27: =IF('🏪 Vendors'!A13="","",'🏪 Vendors'!A13&"") | B27: =IF('🏪 Vendors'!A13="","",'🏪 Vendors'!B13&" Vendor") | C27: =IF('🏪 Vendors'!A13="","",'🏪 Vendors'!D13&"") | D27: =IF('🏪 Vendors'!A13="","",'🏪 Vendors'!E13&"") | E27: =IF('🏪 Vendors'!A13="","","Handled by "&'🏪 Vendors'!C13)
A28: =IF('🏪 Vendors'!A14="","",'🏪 Vendors'!A14&"") | B28: =IF('🏪 Vendors'!A14="","",'🏪 Vendors'!B14&" Vendor") | C28: =IF('🏪 Vendors'!A14="","",'🏪 Vendors'!D14&"") | D28: =IF('🏪 Vendors'!A14="","",'🏪 Vendors'!E14&"") | E28: =IF('🏪 Vendors'!A14="","","Handled by "&'🏪 Vendors'!C14)
A29: =IF('🏪 Vendors'!A15="","",'🏪 Vendors'!A15&"") | B29: =IF('🏪 Vendors'!A15="","",'🏪 Vendors'!B15&" Vendor") | C29: =IF('🏪 Vendors'!A15="","",'🏪 Vendors'!D15&"") | D29: =IF('🏪 Vendors'!A15="","",'🏪 Vendors'!E15&"") | E29: =IF('🏪 Vendors'!A15="","","Handled by "&'🏪 Vendors'!C15)
... A57: =IF('🏪 Vendors'!A43="","",'🏪 Vendors'!A43&"") | B57: =IF('🏪 Vendors'!A43="","",'🏪 Vendors'!B43&" Vendor") | C57: =IF('🏪 Vendors'!A43="","",'🏪 Vendors'!D43&"") | D57: =IF('🏪 Vendors'!A43="","",'🏪 Vendors'!E43&"") | E57: =IF('🏪 Vendors'!A43="","","Handled by "&'🏪 Vendors'!C43)
A59: ✍️ Additional Contacts (manual entry — hotels, transport, etc. not already in Vendors)
A60: Name | B60: Type | C60: Phone | D60: Alternate Phone | E60: Notes
A61: Hotel Sunview — Front Desk | B61: Hotel | C61: +91 90222 33445 | E61: Block booking for out-of-town guests
A77: The first two sections are read-only formulas synced from Wedding Info and Vendors — to change them, edit the source sheet, not here. Only the 'Additional Contacts' section at the bottom is directly editable.

Sheet 📁 Documents
A1: 📁 Documents
A3: Document Name | B3: Category | C3: Related To | D3: Google Drive Link | E3: Uploaded By | F3: Date Added
A4: Grand Palace Banquets — Signed Contract | B4: Contract | C4: Grand Palace Banquets | D4: https://drive.google.com/... | E4: Father | F4: 46235
A45: 'Related To' is free text — type a vendor name (to match Vendor Management) or 'General'. Paste any Google Drive share link directly into the Link column; Google Sheets auto-detects and makes it clickable.

Sheet 🔍 Search
A1: 🔍 Search
A2: Search anything:
A3: Type a name, phone number, item, or keyword above — matching rows appear below automatically. Leave it blank to preview the first few rows of each list.
A5: 👪 Matching Families
A6: Family Name | B6: Village/City | C6: Phone | D6: Invitation
A7: =IFERROR(INDEX('👨‍👩‍👧‍👦 Guests'!B:B,MATCH(1,'👨‍👩‍👧‍👦 Guests'!M:M,0)),"") -> Sharma Family | B7: =IFERROR(INDEX('👨‍👩‍👧‍👦 Guests'!C:C,MATCH(1,'👨‍👩‍👧‍👦 Guests'!M:M,0)),"") -> Pune | C7: =IFERROR(INDEX('👨‍👩‍👧‍👦 Guests'!D:D,MATCH(1,'👨‍👩‍👧‍👦 Guests'!M:M,0)),"") -> +91 98765 11111 | D7: =IFERROR(INDEX('👨‍👩‍👧‍👦 Guests'!G:G,MATCH(1,'👨‍👩‍👧‍👦 Guests'!M:M,0)),"") -> Yes
A8: =IFERROR(INDEX('👨‍👩‍👧‍👦 Guests'!B:B,MATCH(2,'👨‍👩‍👧‍👦 Guests'!M:M,0)),"") | B8: =IFERROR(INDEX('👨‍👩‍👧‍👦 Guests'!C:C,MATCH(2,'👨‍👩‍👧‍👦 Guests'!M:M,0)),"") | C8: =IFERROR(INDEX('👨‍👩‍👧‍👦 Guests'!D:D,MATCH(2,'👨‍👩‍👧‍👦 Guests'!M:M,0)),"") | D8: =IFERROR(INDEX('👨‍👩‍👧‍👦 Guests'!G:G,MATCH(2,'👨‍👩‍👧‍👦 Guests'!M:M,0)),"")
A9: =IFERROR(INDEX('👨‍👩‍👧‍👦 Guests'!B:B,MATCH(3,'👨‍👩‍👧‍👦 Guests'!M:M,0)),"") | B9: =IFERROR(INDEX('👨‍👩‍👧‍👦 Guests'!C:C,MATCH(3,'👨‍👩‍👧‍👦 Guests'!M:M,0)),"") | C9: =IFERROR(INDEX('👨‍👩‍👧‍👦 Guests'!D:D,MATCH(3,'👨‍👩‍👧‍👦 Guests'!M:M,0)),"") | D9: =IFERROR(INDEX('👨‍👩‍👧‍👦 Guests'!G:G,MATCH(3,'👨‍👩‍👧‍👦 Guests'!M:M,0)),"")
A10: =IFERROR(INDEX('👨‍👩‍👧‍👦 Guests'!B:B,MATCH(4,'👨‍👩‍👧‍👦 Guests'!M:M,0)),"") | B10: =IFERROR(INDEX('👨‍👩‍👧‍👦 Guests'!C:C,MATCH(4,'👨‍👩‍👧‍👦 Guests'!M:M,0)),"") | C10: =IFERROR(INDEX('👨‍👩‍👧‍👦 Guests'!D:D,MATCH(4,'👨‍👩‍👧‍👦 Guests'!M:M,0)),"") | D10: =IFERROR(INDEX('👨‍👩‍👧‍👦 Guests'!G:G,MATCH(4,'👨‍👩‍👧‍👦 Guests'!M:M,0)),"")
A11: =IFERROR(INDEX('👨‍👩‍👧‍👦 Guests'!B:B,MATCH(5,'👨‍👩‍👧‍👦 Guests'!M:M,0)),"") | B11: =IFERROR(INDEX('👨‍👩‍👧‍👦 Guests'!C:C,MATCH(5,'👨‍👩‍👧‍👦 Guests'!M:M,0)),"") | C11: =IFERROR(INDEX('👨‍👩‍👧‍👦 Guests'!D:D,MATCH(5,'👨‍👩‍👧‍👦 Guests'!M:M,0)),"") | D11: =IFERROR(INDEX('👨‍👩‍👧‍👦 Guests'!G:G,MATCH(5,'👨‍👩‍👧‍👦 Guests'!M:M,0)),"")
A12: =IFERROR(INDEX('👨‍👩‍👧‍👦 Guests'!B:B,MATCH(6,'👨‍👩‍👧‍👦 Guests'!M:M,0)),"") | B12: =IFERROR(INDEX('👨‍👩‍👧‍👦 Guests'!C:C,MATCH(6,'👨‍👩‍👧‍👦 Guests'!M:M,0)),"") | C12: =IFERROR(INDEX('👨‍👩‍👧‍👦 Guests'!D:D,MATCH(6,'👨‍👩‍👧‍👦 Guests'!M:M,0)),"") | D12: =IFERROR(INDEX('👨‍👩‍👧‍👦 Guests'!G:G,MATCH(6,'👨‍👩‍👧‍👦 Guests'!M:M,0)),"")
A13: =IFERROR(INDEX('👨‍👩‍👧‍👦 Guests'!B:B,MATCH(7,'👨‍👩‍👧‍👦 Guests'!M:M,0)),"") | B13: =IFERROR(INDEX('👨‍👩‍👧‍👦 Guests'!C:C,MATCH(7,'👨‍👩‍👧‍👦 Guests'!M:M,0)),"") | C13: =IFERROR(INDEX('👨‍👩‍👧‍👦 Guests'!D:D,MATCH(7,'👨‍👩‍👧‍👦 Guests'!M:M,0)),"") | D13: =IFERROR(INDEX('👨‍👩‍👧‍👦 Guests'!G:G,MATCH(7,'👨‍👩‍👧‍👦 Guests'!M:M,0)),"")
A14: =IFERROR(INDEX('👨‍👩‍👧‍👦 Guests'!B:B,MATCH(8,'👨‍👩‍👧‍👦 Guests'!M:M,0)),"") | B14: =IFERROR(INDEX('👨‍👩‍👧‍👦 Guests'!C:C,MATCH(8,'👨‍👩‍👧‍👦 Guests'!M:M,0)),"") | C14: =IFERROR(INDEX('👨‍👩‍👧‍👦 Guests'!D:D,MATCH(8,'👨‍👩‍👧‍👦 Guests'!M:M,0)),"") | D14: =IFERROR(INDEX('👨‍👩‍👧‍👦 Guests'!G:G,MATCH(8,'👨‍👩‍👧‍👦 Guests'!M:M,0)),"")
A16: 🏪 Matching Vendors
A17: Vendor Name | B17: Category | C17: Phone | D17: Status
A18: =IFERROR(INDEX('🏪 Vendors'!A:A,MATCH(1,'🏪 Vendors'!M:M,0)),"") -> Grand Palace Banquets | B18: =IFERROR(INDEX('🏪 Vendors'!B:B,MATCH(1,'🏪 Vendors'!M:M,0)),"") -> Hall | C18: =IFERROR(INDEX('🏪 Vendors'!D:D,MATCH(1,'🏪 Vendors'!M:M,0)),"") -> +91 90000 22233 | D18: =IFERROR(INDEX('🏪 Vendors'!J:J,MATCH(1,'🏪 Vendors'!M:M,0)),"") -> Pending
A19: =IFERROR(INDEX('🏪 Vendors'!A:A,MATCH(2,'🏪 Vendors'!M:M,0)),"") | B19: =IFERROR(INDEX('🏪 Vendors'!B:B,MATCH(2,'🏪 Vendors'!M:M,0)),"") | C19: =IFERROR(INDEX('🏪 Vendors'!D:D,MATCH(2,'🏪 Vendors'!M:M,0)),"") | D19: =IFERROR(INDEX('🏪 Vendors'!J:J,MATCH(2,'🏪 Vendors'!M:M,0)),"")
A20: =IFERROR(INDEX('🏪 Vendors'!A:A,MATCH(3,'🏪 Vendors'!M:M,0)),"") | B20: =IFERROR(INDEX('🏪 Vendors'!B:B,MATCH(3,'🏪 Vendors'!M:M,0)),"") | C20: =IFERROR(INDEX('🏪 Vendors'!D:D,MATCH(3,'🏪 Vendors'!M:M,0)),"") | D20: =IFERROR(INDEX('🏪 Vendors'!J:J,MATCH(3,'🏪 Vendors'!M:M,0)),"")
A21: =IFERROR(INDEX('🏪 Vendors'!A:A,MATCH(4,'🏪 Vendors'!M:M,0)),"") | B21: =IFERROR(INDEX('🏪 Vendors'!B:B,MATCH(4,'🏪 Vendors'!M:M,0)),"") | C21: =IFERROR(INDEX('🏪 Vendors'!D:D,MATCH(4,'🏪 Vendors'!M:M,0)),"") | D21: =IFERROR(INDEX('🏪 Vendors'!J:J,MATCH(4,'🏪 Vendors'!M:M,0)),"")
A22: =IFERROR(INDEX('🏪 Vendors'!A:A,MATCH(5,'🏪 Vendors'!M:M,0)),"") | B22: =IFERROR(INDEX('🏪 Vendors'!B:B,MATCH(5,'🏪 Vendors'!M:M,0)),"") | C22: =IFERROR(INDEX('🏪 Vendors'!D:D,MATCH(5,'🏪 Vendors'!M:M,0)),"") | D22: =IFERROR(INDEX('🏪 Vendors'!J:J,MATCH(5,'🏪 Vendors'!M:M,0)),"")
A23: =IFERROR(INDEX('🏪 Vendors'!A:A,MATCH(6,'🏪 Vendors'!M:M,0)),"") | B23: =IFERROR(INDEX('🏪 Vendors'!B:B,MATCH(6,'🏪 Vendors'!M:M,0)),"") | C23: =IFERROR(INDEX('🏪 Vendors'!D:D,MATCH(6,'🏪 Vendors'!M:M,0)),"") | D23: =IFERROR(INDEX('🏪 Vendors'!J:J,MATCH(6,'🏪 Vendors'!M:M,0)),"")
A24: =IFERROR(INDEX('🏪 Vendors'!A:A,MATCH(7,'🏪 Vendors'!M:M,0)),"") | B24: =IFERROR(INDEX('🏪 Vendors'!B:B,MATCH(7,'🏪 Vendors'!M:M,0)),"") | C24: =IFERROR(INDEX('🏪 Vendors'!D:D,MATCH(7,'🏪 Vendors'!M:M,0)),"") | D24: =IFERROR(INDEX('🏪 Vendors'!J:J,MATCH(7,'🏪 Vendors'!M:M,0)),"")
A25: =IFERROR(INDEX('🏪 Vendors'!A:A,MATCH(8,'🏪 Vendors'!M:M,0)),"") | B25: =IFERROR(INDEX('🏪 Vendors'!B:B,MATCH(8,'🏪 Vendors'!M:M,0)),"") | C25: =IFERROR(INDEX('🏪 Vendors'!D:D,MATCH(8,'🏪 Vendors'!M:M,0)),"") | D25: =IFERROR(INDEX('🏪 Vendors'!J:J,MATCH(8,'🏪 Vendors'!M:M,0)),"")
A27: 🛍️ Matching Shopping Items
A28: Item | B28: Category | C28: Responsible | D28: Status
A29: =IFERROR(INDEX('🛍️ Shopping'!A:A,MATCH(1,'🛍️ Shopping'!M:M,0)),"") -> Groom Sherwani | B29: =IFERROR(INDEX('🛍️ Shopping'!B:B,MATCH(1,'🛍️ Shopping'!M:M,0)),"") -> Groom Outfits | C29: =IFERROR(INDEX('🛍️ Shopping'!C:C,MATCH(1,'🛍️ Shopping'!M:M,0)),"") -> Self | D29: =IFERROR(INDEX('🛍️ Shopping'!E:E,MATCH(1,'🛍️ Shopping'!M:M,0)),"") -> Ordered
A30: =IFERROR(INDEX('🛍️ Shopping'!A:A,MATCH(2,'🛍️ Shopping'!M:M,0)),"") | B30: =IFERROR(INDEX('🛍️ Shopping'!B:B,MATCH(2,'🛍️ Shopping'!M:M,0)),"") | C30: =IFERROR(INDEX('🛍️ Shopping'!C:C,MATCH(2,'🛍️ Shopping'!M:M,0)),"") | D30: =IFERROR(INDEX('🛍️ Shopping'!E:E,MATCH(2,'🛍️ Shopping'!M:M,0)),"")
A31: =IFERROR(INDEX('🛍️ Shopping'!A:A,MATCH(3,'🛍️ Shopping'!M:M,0)),"") | B31: =IFERROR(INDEX('🛍️ Shopping'!B:B,MATCH(3,'🛍️ Shopping'!M:M,0)),"") | C31: =IFERROR(INDEX('🛍️ Shopping'!C:C,MATCH(3,'🛍️ Shopping'!M:M,0)),"") | D31: =IFERROR(INDEX('🛍️ Shopping'!E:E,MATCH(3,'🛍️ Shopping'!M:M,0)),"")
A32: =IFERROR(INDEX('🛍️ Shopping'!A:A,MATCH(4,'🛍️ Shopping'!M:M,0)),"") | B32: =IFERROR(INDEX('🛍️ Shopping'!B:B,MATCH(4,'🛍️ Shopping'!M:M,0)),"") | C32: =IFERROR(INDEX('🛍️ Shopping'!C:C,MATCH(4,'🛍️ Shopping'!M:M,0)),"") | D32: =IFERROR(INDEX('🛍️ Shopping'!E:E,MATCH(4,'🛍️ Shopping'!M:M,0)),"")
A33: =IFERROR(INDEX('🛍️ Shopping'!A:A,MATCH(5,'🛍️ Shopping'!M:M,0)),"") | B33: =IFERROR(INDEX('🛍️ Shopping'!B:B,MATCH(5,'🛍️ Shopping'!M:M,0)),"") | C33: =IFERROR(INDEX('🛍️ Shopping'!C:C,MATCH(5,'🛍️ Shopping'!M:M,0)),"") | D33: =IFERROR(INDEX('🛍️ Shopping'!E:E,MATCH(5,'🛍️ Shopping'!M:M,0)),"")
A34: =IFERROR(INDEX('🛍️ Shopping'!A:A,MATCH(6,'🛍️ Shopping'!M:M,0)),"") | B34: =IFERROR(INDEX('🛍️ Shopping'!B:B,MATCH(6,'🛍️ Shopping'!M:M,0)),"") | C34: =IFERROR(INDEX('🛍️ Shopping'!C:C,MATCH(6,'🛍️ Shopping'!M:M,0)),"") | D34: =IFERROR(INDEX('🛍️ Shopping'!E:E,MATCH(6,'🛍️ Shopping'!M:M,0)),"")
A35: =IFERROR(INDEX('🛍️ Shopping'!A:A,MATCH(7,'🛍️ Shopping'!M:M,0)),"") | B35: =IFERROR(INDEX('🛍️ Shopping'!B:B,MATCH(7,'🛍️ Shopping'!M:M,0)),"") | C35: =IFERROR(INDEX('🛍️ Shopping'!C:C,MATCH(7,'🛍️ Shopping'!M:M,0)),"") | D35: =IFERROR(INDEX('🛍️ Shopping'!E:E,MATCH(7,'🛍️ Shopping'!M:M,0)),"")
A36: =IFERROR(INDEX('🛍️ Shopping'!A:A,MATCH(8,'🛍️ Shopping'!M:M,0)),"") | B36: =IFERROR(INDEX('🛍️ Shopping'!B:B,MATCH(8,'🛍️ Shopping'!M:M,0)),"") | C36: =IFERROR(INDEX('🛍️ Shopping'!C:C,MATCH(8,'🛍️ Shopping'!M:M,0)),"") | D36: =IFERROR(INDEX('🛍️ Shopping'!E:E,MATCH(8,'🛍️ Shopping'!M:M,0)),"")
A38: ✅ Matching Tasks
A39: Task | B39: Category | C39: Assigned To | D39: Status
A40: =IFERROR(INDEX('✅ Tasks'!A:A,MATCH(1,'✅ Tasks'!M:M,0)),"") -> Finalize catering menu | B40: =IFERROR(INDEX('✅ Tasks'!B:B,MATCH(1,'✅ Tasks'!M:M,0)),"") -> Catering | C40: =IFERROR(INDEX('✅ Tasks'!C:C,MATCH(1,'✅ Tasks'!M:M,0)),"") -> Mother | D40: =IFERROR(INDEX('✅ Tasks'!G:G,MATCH(1,'✅ Tasks'!M:M,0)),"") -> In Progress
A41: =IFERROR(INDEX('✅ Tasks'!A:A,MATCH(2,'✅ Tasks'!M:M,0)),"") | B41: =IFERROR(INDEX('✅ Tasks'!B:B,MATCH(2,'✅ Tasks'!M:M,0)),"") | C41: =IFERROR(INDEX('✅ Tasks'!C:C,MATCH(2,'✅ Tasks'!M:M,0)),"") | D41: =IFERROR(INDEX('✅ Tasks'!G:G,MATCH(2,'✅ Tasks'!M:M,0)),"")
A42: =IFERROR(INDEX('✅ Tasks'!A:A,MATCH(3,'✅ Tasks'!M:M,0)),"") | B42: =IFERROR(INDEX('✅ Tasks'!B:B,MATCH(3,'✅ Tasks'!M:M,0)),"") | C42: =IFERROR(INDEX('✅ Tasks'!C:C,MATCH(3,'✅ Tasks'!M:M,0)),"") | D42: =IFERROR(INDEX('✅ Tasks'!G:G,MATCH(3,'✅ Tasks'!M:M,0)),"")
A43: =IFERROR(INDEX('✅ Tasks'!A:A,MATCH(4,'✅ Tasks'!M:M,0)),"") | B43: =IFERROR(INDEX('✅ Tasks'!B:B,MATCH(4,'✅ Tasks'!M:M,0)),"") | C43: =IFERROR(INDEX('✅ Tasks'!C:C,MATCH(4,'✅ Tasks'!M:M,0)),"") | D43: =IFERROR(INDEX('✅ Tasks'!G:G,MATCH(4,'✅ Tasks'!M:M,0)),"")
A44: =IFERROR(INDEX('✅ Tasks'!A:A,MATCH(5,'✅ Tasks'!M:M,0)),"") | B44: =IFERROR(INDEX('✅ Tasks'!B:B,MATCH(5,'✅ Tasks'!M:M,0)),"") | C44: =IFERROR(INDEX('✅ Tasks'!C:C,MATCH(5,'✅ Tasks'!M:M,0)),"") | D44: =IFERROR(INDEX('✅ Tasks'!G:G,MATCH(5,'✅ Tasks'!M:M,0)),"")
...
